<mujoco model="mobile_panda">
  <!-- [关键] 相对路径修正：../ 指向项目根目录 -->
  <compiler angle="radian" meshdir="/home/j16/project Centaurus/drp_full/mujoco_menagerie/franka_emika_panda/assets" autolimits="true"/>
  
  <!-- [关键] 移除 implicitfast，使用默认积分器，防止卡死 -->
  <!-- <option integrator="implicitfast"/> -->

  <visual>
    <global offwidth="1920" offheight="1080"/>
  </visual>

  <default>
    <default class="panda">
      <material specular="0.5" shininess="0.25"/>
      <joint armature="0.1" damping="1" axis="0 0 1" range="-2.8973 2.8973"/>
      <general dyntype="none" biastype="affine" ctrlrange="-2.8973 2.8973" forcerange="-87 87"/>
      <default class="visual">
        <geom type="mesh" contype="0" conaffinity="0" group="2"/>
      </default>
      <default class="collision">
        <geom type="mesh" group="3"/>
      </default>
    </default>
    
    <!-- Finger Defaults -->
    <default class="panda_finger">
      <joint axis="0 1 0" type="slide" range="0 0.04" armature="0.001" damping="0.1"/>
      <general dyntype="none" biastype="affine" ctrlrange="0 0.04" forcerange="-100 100"/>
      <default class="finger_visual">
        <geom type="mesh" contype="0" conaffinity="0" group="2"/>
      </default>
      <default class="finger_collision">
        <geom type="mesh" group="3"/>
      </default>
    </default>
    
    <!-- Mobile Base Defaults -->
    <default class="base">
        <joint armature="0.001" damping="10" frictionloss="0.1"/>
        <motor ctrlrange="-1 1" gear="500"/> 
        <geom type="cylinder" rgba="0.2 0.2 0.2 1" condim="3"/>
    </default>
  </default>

  <asset>
    <!-- Materials -->
    <material class="panda" name="white" rgba="1 1 1 1"/>
    <material class="panda" name="off_white" rgba="0.901961 0.921569 0.929412 1"/>
    <material class="panda" name="black" rgba="0.25 0.25 0.25 1"/>
    <material class="panda" name="green" rgba="0 1 0 1"/> 
    <material class="panda" name="light_blue" rgba="0.039216 0.541176 0.780392 1"/>
    <material name="target_mat" rgba="0 1 0 1"/>
    <material name="obstacle_mat" rgba="1 0 0 1"/>
    <material name="floor_mat" specular="0" shininess="0.5" reflectance="0" rgba="0.2 0.2 0.2 1"/>

    <!-- Arm Meshes -->
    <mesh name="link0_c" file="link0.stl"/>
    <mesh name="link1_c" file="link1.stl"/>
    <mesh name="link2_c" file="link2.stl"/>
    <mesh name="link3_c" file="link3.stl"/>
    <mesh name="link4_c" file="link4.stl"/>
    <mesh name="link5_c0" file="link5_collision_0.obj"/>
    <mesh name="link5_c1" file="link5_collision_1.obj"/>
    <mesh name="link5_c2" file="link5_collision_2.obj"/>
    <mesh name="link6_c" file="link6.stl"/>
    <mesh name="link7_c" file="link7.stl"/>
    <mesh file="link0_0.obj"/> <mesh file="link0_1.obj"/> <mesh file="link0_2.obj"/> <mesh file="link0_3.obj"/>
    <mesh file="link0_4.obj"/> <mesh file="link0_5.obj"/> <mesh file="link0_7.obj"/> <mesh file="link0_8.obj"/>
    <mesh file="link0_9.obj"/> <mesh file="link0_10.obj"/> <mesh file="link0_11.obj"/>
    <mesh file="link1.obj"/> <mesh file="link2.obj"/>
    <mesh file="link3_0.obj"/> <mesh file="link3_1.obj"/> <mesh file="link3_2.obj"/> <mesh file="link3_3.obj"/>
    <mesh file="link4_0.obj"/> <mesh file="link4_1.obj"/> <mesh file="link4_2.obj"/> <mesh file="link4_3.obj"/>
    <mesh file="link5_0.obj"/> <mesh file="link5_1.obj"/> <mesh file="link5_2.obj"/>
    <mesh file="link6_0.obj"/> <mesh file="link6_1.obj"/> <mesh file="link6_2.obj"/> <mesh file="link6_3.obj"/>
    <mesh file="link6_4.obj"/> <mesh file="link6_5.obj"/> <mesh file="link6_6.obj"/> <mesh file="link6_7.obj"/>
    <mesh file="link6_8.obj"/> <mesh file="link6_9.obj"/> <mesh file="link6_10.obj"/> <mesh file="link6_11.obj"/>
    <mesh file="link6_12.obj"/> <mesh file="link6_13.obj"/> <mesh file="link6_14.obj"/> <mesh file="link6_15.obj"/>
    <mesh file="link6_16.obj"/>
    <mesh file="link7_0.obj"/> <mesh file="link7_1.obj"/> <mesh file="link7_2.obj"/> <mesh file="link7_3.obj"/>
    <mesh file="link7_4.obj"/> <mesh file="link7_5.obj"/> <mesh file="link7_6.obj"/> <mesh file="link7_7.obj"/>

    <!-- Hand Meshes -->
    <mesh name="hand_0" file="hand_0.obj"/>
    <mesh name="hand_1" file="hand_1.obj"/>
    <mesh name="hand_2" file="hand_2.obj"/>
    <mesh name="hand_3" file="hand_3.obj"/>
    <mesh name="hand_4" file="hand_4.obj"/>
    <mesh name="hand_c" file="hand_0.obj"/> 
    
    <mesh name="finger_0" file="finger_0.obj"/>
    <mesh name="finger_1" file="finger_1.obj"/>
    <mesh name="finger_c" file="finger_0.obj"/> 
  
    <!-- IKEA Assets -->
    <mesh name="mesh_strandmon_wing_chair___nordvalla_dark_gr" file="../../../assets/ikea_processed/strandmon_wing_chair___nordvalla_dark_gr.obj" scale="1.0 1.0 1.0"/>
    <mesh name="mesh_skruvby_sideboard___black_blue_70568720" file="../../../assets/ikea_processed/skruvby_sideboard___black_blue_70568720.obj" scale="1.0 1.0 1.0"/>
    <mesh name="mesh_billy_bookcase___oak_effect_90477385" file="../../../assets/ikea_processed/billy_bookcase___oak_effect_90477385.obj" scale="1.0 1.0 1.0"/>
    <mesh name="mesh_kallax_shelf_unit___white_80275887" file="../../../assets/ikea_processed/kallax_shelf_unit___white_80275887.obj" scale="1.0 1.0 1.0"/>
    <mesh name="mesh_hektar_work_lamp___dark_gray_90349374" file="../../../assets/ikea_processed/hektar_work_lamp___dark_gray_90349374.obj" scale="1.0 1.0 1.0"/>
    <mesh name="mesh_lersta_floorreading_lamp___aluminum_chro" file="../../../assets/ikea_processed/lersta_floorreading_lamp___aluminum_chro.obj" scale="1.0 1.0 1.0"/>
    <mesh name="mesh_dröna_box___white_50467067" file="../../../assets/ikea_processed/dröna_box___white_50467067.obj" scale="1.0 1.0 1.0"/>
    <mesh name="mesh_lack_coffee_table___black_brown_00104291" file="../../../assets/ikea_processed/lack_coffee_table___black_brown_00104291.obj" scale="1.0 1.0 1.0"/>
    <mesh name="mesh_fniss_trash_can___white_40295439" file="../../../assets/ikea_processed/fniss_trash_can___white_40295439.obj" scale="1.0 1.0 1.0"/>
    <mesh name="mesh_buslätt_chair___whitepine_90601139" file="../../../assets/ikea_processed/buslätt_chair___whitepine_90601139.obj" scale="1.0 1.0 1.0"/>
    <mesh name="mesh_hemnes_2_drawer_chest___white_stain_8024" file="../../../assets/ikea_processed/hemnes_2_drawer_chest___white_stain_8024.obj" scale="1.0 1.0 1.0"/>
    <mesh name="mesh_skådis_pegboard_combination_89406365" file="../../../assets/ikea_processed/skådis_pegboard_combination_89406365.obj" scale="1.0 1.0 1.0"/>
    <mesh name="mesh_tjena_storage_box_with_lid___white_black" file="../../../assets/ikea_processed/tjena_storage_box_with_lid___white_black.obj" scale="1.0 1.0 1.0"/>
    <mesh name="mesh_micke_desk___white_80213074" file="../../../assets/ikea_processed/micke_desk___white_80213074.obj" scale="1.0 1.0 1.0"/>
    <mesh name="mesh_vihals_table___whitewhite_39578509" file="../../../assets/ikea_processed/vihals_table___whitewhite_39578509.obj" scale="1.0 1.0 1.0"/>
    <mesh name="mesh_ikea_365+_pot_with_lid___stainless_steel" file="../../../assets/ikea_processed/ikea_365+_pot_with_lid___stainless_steel.obj" scale="1.0 1.0 1.0"/>
    <mesh name="mesh_vittsjö_shelf_unit___white_10305802" file="../../../assets/ikea_processed/vittsjö_shelf_unit___white_10305802.obj" scale="1.0 1.0 1.0"/>
    <mesh name="mesh_tånebro_side_table___indooroutdooranthra" file="../../../assets/ikea_processed/tånebro_side_table___indooroutdooranthra.obj" scale="1.0 1.0 1.0"/>

  </asset>

  <worldbody>
    <light name="top_light" pos="0 0 4" mode="trackcom" diffuse="0.8 0.8 0.8"/>
    <geom name="floor" type="plane" size="10 10 0.1" material="floor_mat" condim="3"/>

    <!-- === MOBILE BASE === -->
    <body name="mobile_base" pos="0 0 0.15"> 
        <joint name="base_x" type="slide" axis="1 0 0" class="base"/>
        <joint name="base_y" type="slide" axis="0 1 0" class="base"/>
        <joint name="base_theta" type="hinge" axis="0 0 1" class="base"/>
        
        <geom type="cylinder" size="0.25 0.15" class="base"/>
        <site name="front_indicator" type="box" size="0.02 0.05 0.01" pos="0.22 0 0.15" rgba="1 0 0 1"/>
        <geom type="cylinder" size="0.1 0.04" pos="0 0.22 -0.1" euler="90 0 0" rgba="0.1 0.1 0.1 1"/>
        <geom type="cylinder" size="0.1 0.04" pos="0 -0.22 -0.1" euler="90 0 0" rgba="0.1 0.1 0.1 1"/>

        <camera name="cam_left" pos="-0.5 0.5 1.0" mode="targetbody" target="link0"/>
        <camera name="cam_right" pos="-0.5 -0.5 1.0" mode="targetbody" target="link0"/>

        <!-- === PANDA ARM === -->
        <body name="link0" childclass="panda" pos="0.1 0 0.2"> 
          <inertial mass="0.629769" pos="-0.041018 -0.00014 0.049974" fullinertia="0.00315 0.00388 0.004285 8.2904e-7 0.00015 8.2299e-6"/>
          <geom mesh="link0_0" material="off_white" class="visual"/>
          <geom mesh="link0_1" material="black" class="visual"/>
          <geom mesh="link0_2" material="off_white" class="visual"/>
          <geom mesh="link0_3" material="black" class="visual"/>
          <geom mesh="link0_4" material="off_white" class="visual"/>
          <geom mesh="link0_5" material="black" class="visual"/>
          <geom mesh="link0_7" material="white" class="visual"/>
          <geom mesh="link0_8" material="white" class="visual"/>
          <geom mesh="link0_9" material="black" class="visual"/>
          <geom mesh="link0_10" material="off_white" class="visual"/>
          <geom mesh="link0_11" material="white" class="visual"/>
          <geom mesh="link0_c" class="collision"/>
          <body name="link1" pos="0 0 0.333">
            <inertial mass="4.970684" pos="0.003875 0.002081 -0.04762" fullinertia="0.70337 0.70661 0.0091170 -0.00013900 0.0067720 0.019169"/>
            <joint name="joint1"/> <geom material="white" mesh="link1" class="visual"/> <geom mesh="link1_c" class="collision"/>
            <body name="link2" quat="1 -1 0 0">
              <inertial mass="0.646926" pos="-0.003141 -0.02872 0.003495" fullinertia="0.0079620 2.8110e-2 2.5995e-2 -3.925e-3 1.0254e-2 7.04e-4"/>
              <joint name="joint2" range="-1.7628 1.7628"/> <geom material="white" mesh="link2" class="visual"/> <geom mesh="link2_c" class="collision"/>
              <body name="link3" pos="0 -0.316 0" quat="1 1 0 0">
                <joint name="joint3"/>
                <inertial mass="3.228604" pos="2.7518e-2 3.9252e-2 -6.6502e-2" fullinertia="3.7242e-2 3.6155e-2 1.083e-2 -4.761e-3 -1.1396e-2 -1.2805e-2"/>
                <geom mesh="link3_0" material="white" class="visual"/> <geom mesh="link3_1" material="white" class="visual"/>
                <geom mesh="link3_2" material="white" class="visual"/> <geom mesh="link3_3" material="black" class="visual"/> <geom mesh="link3_c" class="collision"/>
                <body name="link4" pos="0.0825 0 0" quat="1 1 0 0">
                  <inertial mass="3.587895" pos="-5.317e-2 1.04419e-1 2.7454e-2" fullinertia="2.5853e-2 1.9552e-2 2.8323e-2 7.796e-3 -1.332e-3 8.641e-3"/>
                  <joint name="joint4" range="-3.0718 -0.0698"/> <geom mesh="link4_0" material="white" class="visual"/> <geom mesh="link4_1" material="white" class="visual"/>
                  <geom mesh="link4_2" material="black" class="visual"/> <geom mesh="link4_3" material="white" class="visual"/> <geom mesh="link4_c" class="collision"/>
                  <body name="link5" pos="-0.0825 0.384 0" quat="1 -1 0 0">
                    <inertial mass="1.225946" pos="-1.1953e-2 4.1065e-2 -3.8437e-2" fullinertia="3.5549e-2 2.9474e-2 8.627e-3 -2.117e-3 -4.037e-3 2.29e-4"/>
                    <joint name="joint5"/> <geom mesh="link5_0" material="black" class="visual"/> <geom mesh="link5_1" material="white" class="visual"/>
                    <geom mesh="link5_2" material="white" class="visual"/> <geom mesh="link5_c0" class="collision"/> <geom mesh="link5_c1" class="collision"/> <geom mesh="link5_c2" class="collision"/>
                    <body name="link6" quat="1 1 0 0">
                      <inertial mass="1.666555" pos="6.0149e-2 -1.4117e-2 -1.0517e-2" fullinertia="1.964e-3 4.354e-3 5.433e-3 1.09e-4 -1.158e-3 3.41e-4"/>
                      <joint name="joint6" range="-0.0175 3.7525"/>
                      <geom mesh="link6_0" material="off_white" class="visual"/> <geom mesh="link6_1" material="white" class="visual"/>
                      <geom mesh="link6_2" material="black" class="visual"/> <geom mesh="link6_3" material="white" class="visual"/>
                      <geom mesh="link6_4" material="white" class="visual"/> <geom mesh="link6_5" material="white" class="visual"/>
                      <geom mesh="link6_6" material="white" class="visual"/> <geom mesh="link6_7" material="light_blue" class="visual"/>
                      <geom mesh="link6_8" material="light_blue" class="visual"/> <geom mesh="link6_9" material="black" class="visual"/>
                      <geom mesh="link6_10" material="black" class="visual"/> <geom mesh="link6_11" material="white" class="visual"/>
                      <geom mesh="link6_12" material="green" class="visual"/> <geom mesh="link6_13" material="white" class="visual"/>
                      <geom mesh="link6_14" material="black" class="visual"/> <geom mesh="link6_15" material="black" class="visual"/>
                      <geom mesh="link6_16" material="white" class="visual"/> <geom mesh="link6_c" class="collision"/>
                      <body name="link7" pos="0.088 0 0" quat="1 1 0 0">
                        <inertial mass="7.35522e-01" pos="1.0517e-2 -4.252e-3 6.1597e-2" fullinertia="1.2516e-2 1.0027e-2 4.815e-3 -4.28e-4 -1.196e-3 -7.41e-4"/>
                        <joint name="joint7"/>
                        <geom mesh="link7_0" material="white" class="visual"/> <geom mesh="link7_1" material="black" class="visual"/>
                        <geom mesh="link7_2" material="black" class="visual"/> <geom mesh="link7_3" material="black" class="visual"/>
                        <geom mesh="link7_4" material="black" class="visual"/> <geom mesh="link7_5" material="black" class="visual"/>
                        <geom mesh="link7_6" material="black" class="visual"/> <geom mesh="link7_7" material="white" class="visual"/> <geom mesh="link7_c" class="collision"/>
                        
                        <!-- Hand -->
                        <body name="hand" pos="0 0 0.107" quat="0.92388 0 0 -0.382683">
                          <inertial mass="0.73" pos="-0.01 0 0.03" fullinertia="0.001 0.0025 0.0017 0 0 0"/>
                          <geom mesh="hand_0" material="off_white" class="visual"/>
                          <geom mesh="hand_1" material="black" class="visual"/>
                          <geom mesh="hand_2" material="black" class="visual"/>
                          <geom mesh="hand_3" material="white" class="visual"/>
                          <geom mesh="hand_4" material="off_white" class="visual"/>
                          <geom mesh="hand_c" class="collision"/>

                          <body name="left_finger" pos="0 0 0.0584">
                            <inertial mass="0.015" pos="0 0 0" fullinertia="2.375e-6 2.375e-6 7.5e-7 0 0 0"/>
                            <joint name="finger_joint1" class="panda_finger"/>
                            <geom mesh="finger_0" material="off_white" class="visual"/>
                            <geom mesh="finger_1" material="black" class="visual"/>
                            <geom mesh="finger_c" class="collision"/>
                          </body>

                          <body name="right_finger" pos="0 0 0.0584" quat="0 0 0 1">
                            <inertial mass="0.015" pos="0 0 0" fullinertia="2.375e-6 2.375e-6 7.5e-7 0 0 0"/>
                            <joint name="finger_joint2" class="panda_finger"/>
                            <geom mesh="finger_0" material="off_white" class="visual"/>
                            <geom mesh="finger_1" material="black" class="visual"/>
                            <geom mesh="finger_c" class="collision"/>
                          </body>
                          
                          <site name="tcp_site" pos="0 0 0.1034" size="0.01" rgba="1 0 0 1"/>
                          
                          <body name="wrist_camera_mount" pos="0.04 0 -0.05" euler="0 0.75 1.57">
                              <camera name="cam_wrist" fovy="60"/>
                          </body>
                        </body>
                      </body>
                    </body>
                  </body>
                </body>
              </body>
            </body>
          </body>
        </body>
    </body>
  <body name="fix_skruvby" pos="0.7 0 0" quat="0.7073882691671998 0 0 -0.706825181105366"><geom type="mesh" mesh="mesh_skruvby_sideboard___black_blue_70568720" material="off_white" contype="1" conaffinity="1" density="50" friction="0.8 0.005 0.0001"/></body>
<body name="fix_pot" pos="0.65 -0.3 0.9" quat="1.0 0 0 0.0"><geom type="mesh" mesh="mesh_ikea_365+_pot_with_lid___stainless_steel" material="off_white" contype="1" conaffinity="1" density="50" friction="0.8 0.005 0.0001"/></body>
<body name="fix_vihals" pos="-0.25 0.9 0" quat="1.0 0 0 0.0"><geom type="mesh" mesh="mesh_vihals_table___whitewhite_39578509" material="off_white" contype="1" conaffinity="1" density="50" friction="0.8 0.005 0.0001"/></body>
<body name="fix_buslatt" pos="-0.25 0.7 0" quat="0.0007963267107332633 0 0 0.9999996829318346"><geom type="mesh" mesh="mesh_buslätt_chair___whitepine_90601139" material="off_white" contype="1" conaffinity="1" density="50" friction="0.8 0.005 0.0001"/></body>
    <!-- TARGET_PLACEHOLDER -->
  </worldbody>

  <!-- 移除 Tendon/Equality 以防止物理引擎卡死 -->
  <actuator>
    <motor name="base_x_motor" joint="base_x" ctrlrange="-1 1" class="base"/>
    <motor name="base_y_motor" joint="base_y" ctrlrange="-1 1" class="base"/>
    <motor name="base_theta_motor" joint="base_theta" ctrlrange="-1 1" class="base"/>

    <general class="panda" name="actuator1" joint="joint1" gainprm="4500" biasprm="0 -4500 -450"/>
    <general class="panda" name="actuator2" joint="joint2" gainprm="4500" biasprm="0 -4500 -450" ctrlrange="-1.7628 1.7628"/>
    <general class="panda" name="actuator3" joint="joint3" gainprm="3500" biasprm="0 -3500 -350"/>
    <general class="panda" name="actuator4" joint="joint4" gainprm="3500" biasprm="0 -3500 -350" ctrlrange="-3.0718 -0.0698"/>
    <general class="panda" name="actuator5" joint="joint5" gainprm="2000" biasprm="0 -2000 -200" forcerange="-12 12"/>
    <general class="panda" name="actuator6" joint="joint6" gainprm="2000" biasprm="0 -2000 -200" forcerange="-12 12" ctrlrange="-0.0175 3.7525"/>
    <general class="panda" name="actuator7" joint="joint7" gainprm="2000" biasprm="0 -2000 -200" forcerange="-12 12"/>
    
    <!-- 独立驱动夹爪 -->
    <general class="panda" name="actuator8" joint="finger_joint1" gainprm="100" biasprm="0 -100 -10" ctrlrange="0 0.04"/>
    <general class="panda" name="actuator9" joint="finger_joint2" gainprm="100" biasprm="0 -100 -10" ctrlrange="0 0.04"/>
  </actuator>

  <contact>
    <exclude body1="link0" body2="link1"/>
  </contact>
</mujoco>